在对象里清理自己的资源，每个 downloadRange 实例处理自己相关的资源，range downloader 处理整体相关的资源。

downloadRange 在 pause 的时候，不能把资源清理放在 response 的 close 事件处理中做，随机性太强了。

clearInterval 后和 response.destroy 后仍有可能有事件已经在等待被处理了，所以还会出现 downloadRange 实例被创建和 fs.writeSync 因为 fd 已经被关闭而出错的状况。需要添加一个 finished 变量，已告诉这些漏网之鱼，下载已经结束了。摧毁每个 stream 之后，通过 finished 确保不会有数据再被处理，后面的事情可以不用去管了，直接把剩余的取出的 range 全部保存回去。

```typescript
        for (const [_uuid, stream] of this.responseStreamMap) {
            stream.destroy() // Calling this will cause remaining data in the response to be dropped and the socket to be destroyed.
        } 
        for (const [_uuid, range] of this.rangeMap) {
            this.postPartialRange(range)
        }
```

这样就可以

```typescript
        for (const [uuid, stream] of this.responseStreamMap) {
            stream.destroy() // Calling this will cause remaining data in the response to be dropped and the socket to be destroyed.
            this.postPartialRange(this.rangeMap.get(uuid) as Array<number>)
        } 
```

这样就会漏掉一些 range。

我输出了 responseMap 和 rangeMap 看了看 `console.log(this.responseStreamMap.size, this.rangeMap.size)`，两个的数量不一样。

这是因为从获取 range 到执行 handleResponseStream，添加 stream 到 responseStreamMap，是顺序执行的，但不是同步执行的，中间穿插了其他的代码执行过程。

```javascript
const a = 1
await a
console.log(123)
```

上面这段代码其实等同于

```javascript
new Promise(resolve=>resolve(1)).then(()=>console.log(123))
```

await 后面的代码等同于 then 里面的代码等同于回调函数。await 可以理解为是 then … catch 的另一种写法，代码可读性更好点而已。

pause 的时候有一次出现了无限的 "connect ETIMEDOUT" error。我猜想是在 response 被放入 streamMap 之前的 httprequest 实例引发的，我添加了错误处理，或许不会再出现这样的错误。

httpRequest 可以在 request 上注册错误处理函数，如果 request emit error 信号，就 reject 出去，如果没有错误，就 `request.removeAllListeners('error')` 或者 emitter 的 off 和 removeListener 清除 error handler，然后 resolve [request, response]。

取代多处需要用到的常量，可以用全局变量来保存值，一套用途相似的常量可以用一个结构来保存，比如 enum，静态类或一个全局对象 {[key: string]: string} 来保存这些属性。

用以下代码捕获 Electron 的未能捕获的错误：

```javascript
process.on('uncaughtException', (error) => {
    logger.info('error:', error)
})
```